
C:\Syslog\Syslog2.0>python syslog_server.py update
Traceback (most recent call last):
  File "C:\Syslog\Syslog2.0\syslog_server.py", line 7, in <module>
    from handler_dispatcher import handle_syslog
  File "C:\Syslog\Syslog2.0\handler_dispatcher.py", line 4, in <module>
    from handlers.cisco_ise_handler import handle_cisco_ise_syslog
  File "C:\Syslog\Syslog2.0\handlers\cisco_ise_handler.py", line 4, in <module>
    from handlers.cisco_ise_failed_attempts_handler import handle_cisco_ise_failed_attempts
  File "C:\Syslog\Syslog2.0\handlers\cisco_ise_failed_attempts_handler.py", line 4, in <module>
    from database_utils import fta_inserter, fwa_inserter, fla_inserter
  File "C:\Syslog\Syslog2.0\database_utils.py", line 21, in <module>
    connection_pool = ThreadedConnectionPool(min_conn, max_conn, DATABASE_URL)
  File "C:\Program Files\Python310\lib\site-packages\psycopg2\pool.py", line 161, in __init__
    AbstractConnectionPool.__init__(
  File "C:\Program Files\Python310\lib\site-packages\psycopg2\pool.py", line 59, in __init__
    self._connect()
  File "C:\Program Files\Python310\lib\site-packages\psycopg2\pool.py", line 63, in _connect
    conn = psycopg2.connect(*self._args, **self._kwargs)
  File "C:\Program Files\Python310\lib\site-packages\psycopg2\__init__.py", line 122, in connect
    conn = _connect(dsn, connection_factory=connection_factory, **kwasync)
psycopg2.OperationalError: connection to server at "localhost" (::1), port 5432 failed: FATAL:  sorry, too many clients already
